Workbook

Sheet Danh muc van ban
A1: STT | B1: Nhóm | C1: Số hiệu | D1: Loại VB | E1: Tên / trích yếu | F1: Tên file | G1: Thư mục | H1: Định dạng gốc | I1: Số trang | J1: Ký tự TB/trang | K1: Tình trạng file | L1: Link nguồn | M1: Ghi chú | N1: Nguồn tạo PDF (theo metadata) | O1: PDF Creator | P1: PDF Producer | Q1: Ngày tạo PDF | R1: Chữ ký số
A2: 1 | B2: I. Quản lý thuế | C2: 108/2025/QH15 | D2: Luật | E2: Luật Quản lý thuế | F2: L108_2025_QH15.pdf | G2: raw/I. Quan ly thue | H2: PDF scan (chụp hình) | I2: 65 | J2: 2 | K2: Có file | L2: https://datafiles.chinhphu.vn/cpp/files/vbpq/2026/01/108-qh15.signed.pdf | N2: Máy scan (Smart Touch 1.9) | O2: Smart Touch 1.9 | P2: Kodak Alaris Inc. ; modified using iTextSharp™ 5.5.5 ©2000-2014 iText Group NV (AGPL-version) | Q2: 2026-01-10 | R2: Có
A3: 2 | B3: I. Quản lý thuế | C3: 252/2026/NĐ-CP | D3: Nghị định | E3: Nghị định quy định chi tiết một số điều và biện pháp để tổ chức, hướng dẫn thi hành Luật Quản lý thuế | F3: ND252_2026.pdf | G3: raw/I. Quan ly thue | H3: PDF scan (chụp hình) | I3: 133 | J3: 1 | K3: Có file | L3: https://datafiles.chinhphu.vn/cpp/files/vbpq/2026/7/252-ndcp.signed.pdf | N3: Máy scan (Smart Touch 1.9) | O3: Smart Touch 1.9 | P3: Kodak Alaris Inc. ; modified using iTextSharp™ 5.5.5 ©2000-2014 iText Group NV (AGPL-version) | Q3: 2026-07-03 | R3: Có
A4: 3 | B4: I. Quản lý thuế | C4: 255/2026/NĐ-CP | D4: Nghị định | E4: Nghị định quy định về quản lý thuế đối với các giao dịch liên kết của những doanh nghiệp có quan hệ liên kết | F4: ND255_2026.pdf | G4: raw/I. Quan ly thue | H4: PDF scan (chụp hình) | I4: 77 | J4: 2 | K4: Có file | L4: https://datafiles.chinhphu.vn/cpp/files/vbpq/2026/7/255-ndcp.signed.pdf | N4: Máy scan (Smart Touch 1.9) | O4: Smart Touch 1.9 | P4: Kodak Alaris Inc. ; modified using iTextSharp™ 5.5.5 ©2000-2014 iText Group NV (AGPL-version) | Q4: 2026-07-06 | R4: Có
A5: 4 | B5: I. Quản lý thuế | C5: 125/2020/NĐ-CP | D5: Nghị định | E5: Nghị định quy định xử phạt vi phạm hành chính về thuế, hóa đơn | F5: ND125_2020.pdf | G5: raw/I. Quan ly thue | H5: PDF scan (chụp hình) | I5: 87 | J5: 2 | K5: Có file | L5: https://datafiles.chinhphu.vn/cpp/files/vbpq/2020/10/125.signed.pdf | N5: Máy scan (Smart Touch 1.8) | O5: Smart Touch 1.8 | P5: Kodak Alaris Inc. ; modified using VGCA.Base 5.2.1 (c) 1T3XT BVBA | Q5: 2020-10-21 | R5: Có
A6: 5 | B6: I. Quản lý thuế | C6: 310/2025/NĐ-CP | D6: Nghị định | E6: Nghị định sửa đổi, bổ sung một số điều của Nghị định số 125/2020/NĐ-CP ngày 19 tháng 10 năm 2020 của Chính phủ quy định xử phạt vi phạm hành chính về thuế, hóa đơn | F6: ND310_2025.pdf | G6: raw/I. Quan ly thue | H6: PDF scan (chụp hình) | I6: 16 | J6: 9 | K6: Có file | L6: https://datafiles.chinhphu.vn/cpp/files/vbpq/2025/12/310-cp.signed.pdf | N6: Máy scan (Smart Touch 1.9) | O6: Smart Touch 1.9 | P6: Kodak Alaris Inc. ; modified using iTextSharp™ 5.5.5 ©2000-2014 iText Group NV (AGPL-version) | Q6: 2025-12-04 | R6: Có
A7: 6 | B7: I. Quản lý thuế | C7: 291/2026/NĐ-CP | D7: Nghị định | E7: Nghị định sửa đổi, bổ sung một số điều của Nghị định số 125/2020/NĐ-CP quy định xử phạt vi phạm hành chính về thuế, hóa đơn được sửa đổi, bổ sung bởi Nghị định số 102/2021/NĐ-CP và Nghị định số 310/2025/NĐ-CP | F7: ND291_2026.pdf | G7: raw/I. Quan ly thue | H7: PDF scan (chụp hình) | I7: 3 | J7: 62 | K7: Có file | L7: https://datafiles.chinhphu.vn/cpp/files/vbpq/2026/7/291_2026_nd-cp_21072026-signed.signed.pdf | N7: Không rõ (VGCASignService 1.0.11 ©2014 VGCA - Ban Co yeu Chinh phu; modified using iTextSharp™ 5.5.5 ©2000-2014 iText Group NV (AGPL-version)) | P7: VGCASignService 1.0.11 ©2014 VGCA - Ban Co yeu Chinh phu; modified using iTextSharp™ 5.5.5 ©2000-2014 iText Group NV (AGPL-version) | Q7: 2026-07-22 | R7: Có
A8: 7 | B8: I. Quản lý thuế | C8: 89/2026/TT-BTC | D8: Thông tư | E8: Thông tư quy định chi tiết một số điều của Luật Quản lý thuế và Nghị định số 252/2026/NĐ-CP của Chính phủ quy định chi tiết một số điều và biện pháp để tổ chức, hướng dẫn thi hành Luật Quản lý thuế | F8: TT89_2026_BTC.pdf | G8: raw/I. Quan ly thue | H8: PDF scan (chụp hình) | I8: 839 | J8: 0 | K8: Có file | L8: https://datafiles.chinhphu.vn/cpp/files/vbpq/2026/7/89-btc.signed.pdf | N8: Máy scan (IMIP Universal Scan) | O8: IMIP Universal Scan | P8: GdPicture.NET; modified using iTextSharp™ 5.5.5 ©2000-2014 iText Group NV (AGPL-version) | Q8: 2026-07-15 | R8: Có
A9: 8 | B9: I. Quản lý thuế | C9: 90/2026/TT-BTC | D9: Thông tư | E9: Thông tư quy định về đăng ký thuế | F9: TT90_2026_BTC.pdf | G9: raw/I. Quan ly thue | H9: PDF scan (chụp hình) | I9: 196 | J9: 1 | K9: Có file | L9: https://datafiles.chinhphu.vn/cpp/files/vbpq/2026/7/90-btc.signed.pdf | N9: Máy scan (IMIP Universal Scan) | O9: IMIP Universal Scan | P9: GdPicture.NET; modified using iTextSharp™ 5.5.5 ©2000-2014 iText Group NV (AGPL-version) | Q9: 2026-07-09 | R9: Có
A10: 9 | B10: II. Hóa đơn điện tử | C10: 254/2026/NĐ-CP | D10: Nghị định | E10: Nghị định quy định chi tiết một số điều và biện pháp để tổ chức, hướng dẫn thi hành Luật Quản lý thuế số 108/2025/QH15 về hóa đơn điện tử, chứng từ điện tử | F10: ND254_2026.pdf | G10: raw/II. Hoa don dien tu | H10: PDF scan (chụp hình) | I10: 55 | J10: 3 | K10: Có file | L10: https://datafiles.chinhphu.vn/cpp/files/vbpq/2026/7/254-ndcp.signed.pdf | N10: Máy scan (Smart Touch 1.9) | O10: Smart Touch 1.9 | P10: Kodak Alaris Inc. ; modified using iTextSharp™ 5.5.5 ©2000-2014 iText Group NV (AGPL-version) | Q10: 2026-07-03 | R10: Có
A11: 10 | B11: II. Hóa đơn điện tử | C11: 91/2026/TT-BTC | D11: Thông tư | E11: Thông tư quy định một số điều của Luật Quản lý thuế và Nghị định số 254/2026/NĐ-CP của Chính phủ quy định chi tiết một số điều và biện pháp để tổ chức, hướng dẫn thi hành Luật Quản lý thuế số 108/2025/QH15 về hóa đơn điện tử, chứng từ điện tử | F11: TT91_2026_BTC.pdf | G11: raw/II. Hoa don dien tu | H11: PDF scan (chụp hình) | I11: 97 | J11: 2 | K11: Có file | L11: https://datafiles.chinhphu.vn/cpp/files/vbpq/2026/7/91-btc.signed.pdf | N11: Máy scan (Smart Touch 1.9) | O11: Smart Touch 1.9 | P11: Kodak Alaris Inc. ; modified using iTextSharp™ 5.5.5 ©2000-2014 iText Group NV (AGPL-version) | Q11: 2026-07-28 | R11: Có
A12: 11 | B12: III. Thuế GTGT | C12: 48/2024/QH15 | D12: Luật | E12: Luật Thuế giá trị gia tăng | F12: L48_2024_QH15.pdf | G12: raw/III. Thue GTGT | H12: PDF có text (xuất từ phần mềm khác) | I12: 20 | J12: 2284 | K12: Có file | L12: https://datafiles.chinhphu.vn/cpp/files/vbpq/2025/01/luat48.pdf | N12: Không có metadata (thường là bản Công báo điện tử) | R12: Có
A13: 12 | B13: III. Thuế GTGT | C13: 149/2025/QH15 | D13: Luật | E13: Luật sửa đổi, bổ sung một số điều của Luật Thuế giá trị gia tăng | F13: L149_2025_QH15.pdf | G13: raw/III. Thue GTGT | H13: PDF scan (chụp hình) | I13: 2 | J13: 74 | K13: Có file | L13: https://datafiles.chinhphu.vn/cpp/files/vbpq/2026/01/luat149.signed.pdf | N13: Máy scan (Smart Touch 1.9) | O13: Smart Touch 1.9 | P13: Kodak Alaris Inc. ; modified using iTextSharp™ 5.5.5 ©2000-2014 iText Group NV (AGPL-version) | Q13: 2026-01-12 | R13: Có
A14: 13 | B14: III. Thuế GTGT | C14: 09/2026/QH16 | D14: Luật | E14: Luật sửa đổi, bổ sung một số điều của Luật Thuế thu nhập cá nhân, Luật Thuế giá trị gia tăng, Luật Thuế thu nhập doanh nghiệp và Luật Thuế tiêu thụ đặc biệt | F14: L09_2026_QH16.pdf | G14: raw/III. Thue GTGT | H14: PDF scan (chụp hình) | I14: 2 | J14: 74 | K14: Có file | L14: https://datafiles.chinhphu.vn/cpp/files/vbpq/2026/5/09-qh.signed.pdf | N14: Máy scan (Smart Touch 1.9) | O14: Smart Touch 1.9 | P14: Kodak Alaris Inc. ; modified using iTextSharp™ 5.5.5 ©2000-2014 iText Group NV (AGPL-version) | Q14: 2026-05-15 | R14: Có
A15: 14 | B15: III. Thuế GTGT | C15: 181/2025/NĐ-CP | D15: Nghị định | E15: Nghị định quy định chi tiết thi hành một số điều của Luật Thuế giá trị gia tăng | F15: ND181_2025.pdf | G15: raw/III. Thue GTGT | H15: PDF scan (chụp hình) | I15: 75 | J15: 2 | K15: Có file | L15: https://datafiles.chinhphu.vn/cpp/files/vbpq/2025/7/181nd.signed.pdf | N15: Máy scan (Smart Touch 1.9) | O15: Smart Touch 1.9 | P15: Kodak Alaris Inc. ; modified using iTextSharp™ 5.5.5 ©2000-2014 iText Group NV (AGPL-version) | Q15: 2025-07-03 | R15: Có
A16: 15 | B16: III. Thuế GTGT | C16: 174/2025/NĐ-CP | D16: Nghị định | E16: Nghị định quy định chính sách giảm thuế giá trị gia tăng theo Nghị quyết số 204/2025/QH15 ngày 17 tháng 6 năm 2025 của Quốc hội | F16: ND174_2025.pdf | G16: raw/III. Thue GTGT | H16: PDF scan (chụp hình) | I16: 56 | J16: 3 | K16: Có file | L16: https://datafiles.chinhphu.vn/cpp/files/vbpq/2025/7/174nd.signed.pdf | N16: Máy scan (Smart Touch 1.9) | O16: Smart Touch 1.9 | P16: Kodak Alaris Inc. ; modified using iTextSharp™ 5.5.5 ©2000-2014 iText Group NV (AGPL-version) | Q16: 2025-07-03 | R16: Có
A17: 16 | B17: III. Thuế GTGT | C17: 359/2025/NĐ-CP | D17: Nghị định | E17: Nghị định sửa đổi, bổ sung một số điều của Nghị định số 181/2025/NĐ-CP ngày 01 tháng 7 năm 2025 của Chính phủ quy định chi tiết thi hành một số điều của Luật Thuế giá trị gia tăng | F17: ND359_2025.pdf | G17: raw/III. Thue GTGT | H17: PDF scan (chụp hình) | I17: 3 | J17: 49 | K17: Có file | L17: https://datafiles.chinhphu.vn/cpp/files/vbpq/2026/01/359-nd.signed.pdf | N17: Máy scan (Smart Touch 1.9) | O17: Smart Touch 1.9 | P17: Kodak Alaris Inc. ; modified using iTextSharp™ 5.5.5 ©2000-2014 iText Group NV (AGPL-version) | Q17: 2026-01-05 | R17: Có
A18: 17 | B18: III. Thuế GTGT | C18: 144/2026/NĐ-CP | D18: Nghị định | E18: Nghị định sửa đổi, bổ sung một số điều của Nghị định số 181/2025/NĐ-CP quy định chi tiết thi hành một số điều của Luật Thuế giá trị gia tăng đã được sửa đổi, bổ sung bởi Nghị định số 359/2025/NĐ-CP | F18: ND144_2026.pdf | G18: raw/III. Thue GTGT | H18: PDF scan (chụp hình) | I18: 23 | J18: 6 | K18: Có file | L18: https://datafiles.chinhphu.vn/cpp/files/vbpq/2026/4/144-ndcp.signed.pdf | N18: Máy scan (Smart Touch 1.9) | O18: Smart Touch 1.9 | P18: Kodak Alaris Inc. ; modified using iTextSharp™ 5.5.5 ©2000-2014 iText Group NV (AGPL-version) | Q18: 2026-05-07 | R18: Có
A19: 18 | B19: III. Thuế GTGT | C19: 69/2025/TT-BTC | D19: Thông tư | E19: Thông tư quy định chi tiết một số điều của Luật Thuế giá trị gia tăng và hướng dẫn thực hiện Nghị định số 181/2025/NĐ-CP ngày 01 tháng 7 năm 2025 của Chính phủ quy định chi tiết thi hành một số điều của Luật Thuế giá trị gia tăng | F19: TT69_2025_BTC.pdf | G19: raw/III. Thue GTGT | H19: PDF scan (chụp hình) | I19: 21 | J19: 7 | K19: Có file | L19: https://datafiles.chinhphu.vn/cpp/files/vbpq/2025/7/69-btc.signed.pdf | N19: Máy scan (Smart Touch 1.9) | O19: Smart Touch 1.9 | P19: Kodak Alaris Inc. ; modified using iTextSharp™ 5.5.5 ©2000-2014 iText Group NV (AGPL-version) | Q19: 2025-07-04 | R19: Có
A20: 19 | B20: III. Thuế GTGT | C20: 77/2025/TT-BTC | D20: Thông tư | E20: Thông tư quy định chi tiết các dịch vụ kinh doanh chứng khoán và chuyển nhượng chứng khoán theo Nghị định số 181/2025/NĐ-CP ngày 01 tháng 7 năm 2025 của Chính phủ quy định chi tiết thi hành một số điều của Luật Thuế giá trị gia tăng | F20: TT77_2025_BTC.pdf | G20: raw/III. Thue GTGT | H20: PDF scan (chụp hình) | I20: 3 | J20: 0 | K20: Có file | L20: https://datafiles.chinhphu.vn/cpp/files/vbpq/2025/7/77-btc.pdf | N20: Không rõ (Haru Free PDF Library 2.1.0) | P20: Haru Free PDF Library 2.1.0 | R20: Không
A21: 20 | B21: III. Thuế GTGT | C21: 101/2025/TT-BNNMT | D21: Thông tư | E21: Thông tư hướng dẫn các loại máy chuyên dùng khác phục vụ cho sản xuất nông nghiệp chưa được quy định tại khoản 6 Điều 19 Nghị định số 181/2025/NĐ-CP ngày 01 tháng 7 năm 2025 của Chính phủ quy định chi tiết thi hành một số điều của Luật Thuế giá trị gia tăng | F21: TT101_2025_BNNMT.pdf | G21: raw/III. Thue GTGT | H21: PDF convert từ Word | I21: 5 | J21: 1624 | K21: Có file | L21: https://datafiles.chinhphu.vn/cpp/files/vbpq/2026/01/101-bnnmt.pdf | M21: Số 101 và ngày 31/12/2025 được điền tay trên file; file không có trang chữ ký | N21: Microsoft® Word 2016 | O21: Microsoft® Word 2016 | P21: Microsoft® Word 2016; modified using iTextSharp™ 5.5.9 ©2000-2016 iText Group NV (AGPL-version) | Q21: 2026-01-27 | R21: Có
A22: 21 | B22: IV. Thuế TNCN | C22: 109/2025/QH15 | D22: Luật | E22: Luật Thuế thu nhập cá nhân | F22: L109_2025_QH15.pdf | G22: raw/IV. Thue thu nhap ca nhan | H22: PDF scan (chụp hình) | I22: 15 | J22: 0 | K22: Có file | L22: https://datafiles.chinhphu.vn/cpp/files/vbpq/2026/01/luat109-2025.pdf | N22: Máy scan (HP Scan) | O22: HP Scan | P22: HP Scan Extended Application; modified using iTextSharp™ 5.5.9 ©2000-2016 iText Group NV (AGPL-version) | Q22: 2025-12-24 | R22: Có
A23: 22 | B23: IV. Thuế TNCN | C23: 253/2026/NĐ-CP | D23: Nghị định | E23: Nghị định quy định chi tiết một số điều và biện pháp để tổ chức, hướng dẫn thi hành Luật Thuế thu nhập cá nhân | F23: ND253_2026.pdf | G23: raw/IV. Thue thu nhap ca nhan | H23: PDF scan (chụp hình) | I23: 61 | J23: 2 | K23: Có file | L23: https://datafiles.chinhphu.vn/cpp/files/vbpq/2026/7/253m-ndcp.signed.pdf | N23: Máy scan (Smart Touch 1.9) | O23: Smart Touch 1.9 | P23: Kodak Alaris Inc. ; modified using iTextSharp™ 5.5.5 ©2000-2014 iText Group NV (AGPL-version) | Q23: 2026-07-06 | R23: Có
A24: 23 | B24: IV. Thuế TNCN | C24: 87/2026/TT-BTC | D24: Thông tư | E24: Thông tư quy định chi tiết một số điều của Luật Thuế thu nhập cá nhân và Nghị định số 253/2026/NĐ-CP của Chính phủ quy định chi tiết một số điều và biện pháp để tổ chức, hướng dẫn thi hành Luật Thuế thu nhập cá nhân | F24: TT87_2026_BTC.pdf | G24: raw/IV. Thue thu nhap ca nhan | H24: PDF scan (chụp hình) | I24: 6 | J24: 39 | K24: Có file | L24: https://datafiles.chinhphu.vn/cpp/files/vbpq/2026/7/87-btc.signed.pdf | N24: Máy scan (IMIP Universal Scan) | O24: IMIP Universal Scan | P24: GdPicture.NET; modified using iTextSharp™ 5.5.5 ©2000-2014 iText Group NV (AGPL-version) | Q24: 2026-07-03 | R24: Có
A25: 24 | B25: V. Thuế TNDN | C25: 67/2025/QH15 | D25: Luật | E25: Luật Thuế thu nhập doanh nghiệp | F25: L67_2025_QH15.pdf | G25: raw/V. Thue thu nhap doanh nghiep | H25: PDF scan (chụp hình) | I25: 21 | J25: 7 | K25: Có file | L25: https://datafiles.chinhphu.vn/cpp/files/vbpq/2025/7/67qh.signed.pdf | N25: Máy scan (Smart Touch 1.9) | O25: Smart Touch 1.9 | P25: Kodak Alaris Inc. ; modified using iTextSharp™ 5.5.5 ©2000-2014 iText Group NV (AGPL-version) | Q25: 2025-07-16 | R25: Có
A26: 25 | B26: V. Thuế TNDN | C26: 320/2025/NĐ-CP | D26: Nghị định | E26: Nghị định quy định chi tiết một số điều và biện pháp để tổ chức, hướng dẫn thi hành Luật Thuế thu nhập doanh nghiệp | F26: ND320_2025.pdf | G26: raw/V. Thue thu nhap doanh nghiep | H26: PDF scan (chụp hình) | I26: 76 | J26: 2 | K26: Có file | L26: https://datafiles.chinhphu.vn/cpp/files/vbpq/2025/12/320-ndcp.signed.pdf | N26: Máy scan (Smart Touch 1.9) | O26: Smart Touch 1.9 | P26: Kodak Alaris Inc. ; modified using iTextSharp™ 5.5.5 ©2000-2014 iText Group NV (AGPL-version) | Q26: 2025-12-17 | R26: Có
A27: 26 | B27: V. Thuế TNDN | C27: 20/2026/NĐ-CP | D27: Nghị định | E27: Nghị định quy định chi tiết và hướng dẫn thi hành một số điều của Nghị quyết số 198/2025/QH15 ngày 17 tháng 5 năm 2025 của Quốc hội về một số cơ chế, chính sách đặc biệt phát triển kinh tế tư nhân | F27: ND20_2026.pdf | G27: raw/V. Thue thu nhap doanh nghiep | H27: PDF scan (chụp hình) | I27: 23 | J27: 6 | K27: Có file | L27: https://datafiles.chinhphu.vn/cpp/files/vbpq/2026/01/20nd.signed.pdf | M27: Danh mục ghi "hướng dẫn Luật Thuế TNDN" nhưng bản gốc là Nghị định hướng dẫn Nghị quyết 198/2025/QH15 về phát triển kinh tế tư nhân (có ưu đãi thuế TNDN) | N27: Máy scan (Smart Touch 1.9) | O27: Smart Touch 1.9 | P27: Kodak Alaris Inc. ; modified using iTextSharp™ 5.5.5 ©2000-2014 iText Group NV (AGPL-version) | Q27: 2026-01-16 | R27: Có
A28: 27 | B28: V. Thuế TNDN | C28: 141/2026/NĐ-CP | D28: Nghị định | E28: Nghị định sửa đổi, bổ sung một số điều của Nghị định số 68/2026/NĐ-CP quy định về chính sách thuế đối với hộ kinh doanh, cá nhân kinh doanh và Nghị định số 320/2025/NĐ-CP quy định chi tiết một số điều và biện pháp để tổ chức, hướng dẫn thi hành Luật Thuế thu nhập doanh nghiệp | F28: ND141_2026.pdf | G28: raw/V. Thue thu nhap doanh nghiep | H28: PDF scan (chụp hình) | I28: 4 | J28: 37 | K28: Có file | L28: https://datafiles.chinhphu.vn/cpp/files/vbpq/2026/4/141-ndcp.signed.pdf | M28: Có ở cả nhóm V và VI (2 file giống hệt nhau) – tính là 1 văn bản | N28: Máy scan (Smart Touch 1.9) | O28: Smart Touch 1.9 | P28: Kodak Alaris Inc. ; modified using iTextSharp™ 5.5.5 ©2000-2014 iText Group NV (AGPL-version) | Q28: 2026-05-04 | R28: Có
A29: 28 | B29: V. Thuế TNDN | C29: 245/2026/NĐ-CP | D29: Nghị định | E29: Nghị định gia hạn thời hạn nộp thuế giá trị gia tăng, thuế thu nhập doanh nghiệp, thuế thu nhập cá nhân và tiền thuê đất trong năm 2026 | F29: ND245_2026.pdf | G29: raw/V. Thue thu nhap doanh nghiep | H29: PDF scan (chụp hình) | I29: 11 | J29: 13 | K29: Có file | L29: https://datafiles.chinhphu.vn/cpp/files/vbpq/2026/6/245-ndcp.signed.pdf | N29: Máy scan (Smart Touch 1.9) | O29: Smart Touch 1.9 | P29: Kodak Alaris Inc. ; modified using iTextSharp™ 5.5.5 ©2000-2014 iText Group NV (AGPL-version) | Q29: 2026-06-30 | R29: Có
A30: 29 | B30: V. Thuế TNDN | C30: 20/2026/TT-BTC | D30: Thông tư | E30: Thông tư quy định chi tiết một số điều của Luật Thuế thu nhập doanh nghiệp và Nghị định số 320/2025/NĐ-CP ngày 15 tháng 12 năm 2025 của Chính phủ quy định chi tiết một số điều và biện pháp để tổ chức, hướng dẫn thi hành Luật Thuế thu nhập doanh nghiệp | F30: TT20_2026_BTC.pdf | G30: raw/V. Thue thu nhap doanh nghiep | H30: PDF scan (chụp hình) | I30: 22 | J30: 4 | K30: Có file | L30: https://datafiles.chinhphu.vn/cpp/files/vbpq/2026/3/20-btc.pdf | N30: Máy scan (IMIP Universal Scan) | O30: IMIP Universal Scan | P30: GdPicture.NET; modified using iTextSharp™ 5.5.6 ©2000-2014 iText Group NV (AGPL-version) | Q30: 2026-03-13 | R30: Có
A31: 30 | B31: VI. Hộ kinh doanh | C31: 68/2026/NĐ-CP | D31: Nghị định | E31: Nghị định quy định về chính sách thuế và quản lý thuế đối với hộ kinh doanh, cá nhân kinh doanh | F31: ND68_2026.pdf | G31: raw/VI. Ho kinh doanh ca nhan kinh doanh | H31: PDF scan (chụp hình) | I31: 19 | J31: 8 | K31: Có file | L31: https://datafiles.chinhphu.vn/cpp/files/vbpq/2026/3/68-ndcp.signed.pdf | N31: Máy scan (Smart Touch 1.9) | O31: Smart Touch 1.9 | P31: Kodak Alaris Inc. ; modified using iTextSharp™ 5.5.5 ©2000-2014 iText Group NV (AGPL-version) | Q31: 2026-03-06 | R31: Có
A32: 31 | B32: VI. Hộ kinh doanh | C32: 141/2026/NĐ-CP | D32: Nghị định | E32: Nghị định sửa đổi, bổ sung một số điều của Nghị định số 68/2026/NĐ-CP quy định về chính sách thuế đối với hộ kinh doanh, cá nhân kinh doanh và Nghị định số 320/2025/NĐ-CP quy định chi tiết một số điều và biện pháp để tổ chức, hướng dẫn thi hành Luật Thuế thu nhập doanh nghiệp | F32: ND141_2026.pdf | G32: raw/VI. Ho kinh doanh ca nhan kinh doanh | H32: PDF scan (chụp hình) | I32: 4 | J32: 37 | K32: Có file | L32: https://datafiles.chinhphu.vn/cpp/files/vbpq/2026/4/141-ndcp.signed.pdf | M32: Có ở cả nhóm V và VI (2 file giống hệt nhau) – tính là 1 văn bản | N32: Máy scan (Smart Touch 1.9) | O32: Smart Touch 1.9 | P32: Kodak Alaris Inc. ; modified using iTextSharp™ 5.5.5 ©2000-2014 iText Group NV (AGPL-version) | Q32: 2026-05-04 | R32: Có
A33: 32 | B33: VI. Hộ kinh doanh | C33: 152/2025/TT-BTC | D33: Thông tư | E33: Thông tư hướng dẫn kế toán cho các hộ kinh doanh, cá nhân kinh doanh | F33: TT152_2025_BTC.pdf | G33: raw/VI. Ho kinh doanh ca nhan kinh doanh | H33: PDF scan (chụp hình) | I33: 14 | J33: 6 | K33: Có file | L33: https://datafiles.chinhphu.vn/cpp/files/vbpq/2026/01/152-btc.pdf | M33: Thuộc cả nhóm VI và VIII, file nằm ở nhóm VI – tính là 1 văn bản (đã xóa bản trùng TT52_2025_BTC.pdf do Long đặt sai tên) | N33: Máy scan (IMIP Universal Scan) | O33: IMIP Universal Scan | P33: GdPicture.NET; modified using iTextSharp™ 5.5.6 ©2000-2014 iText Group NV (AGPL-version) | Q33: 2026-01-06 | R33: Có
A34: 33 | B34: VI. Hộ kinh doanh | C34: 18/2026/TT-BTC | D34: Thông tư | E34: Thông tư quy định về hồ sơ, thủ tục quản lý thuế đối với hộ kinh doanh, cá nhân kinh doanh | F34: TT18_2026_BTC.pdf | G34: raw/VI. Ho kinh doanh ca nhan kinh doanh | H34: PDF scan (chụp hình) | I34: 44 | J34: 3 | K34: Có file | L34: https://datafiles.chinhphu.vn/cpp/files/vbpq/2026/3/18-btc.signed.pdf | N34: Máy scan (Smart Touch 1.9) | O34: Smart Touch 1.9 | P34: Kodak Alaris Inc. ; modified using iTextSharp™ 5.5.5 ©2000-2014 iText Group NV (AGPL-version) | Q34: 2026-03-12 | R34: Có
A35: 34 | B35: VI. Hộ kinh doanh | C35: 50/2026/TT-BTC | D35: Thông tư | E35: Thông tư sửa đổi, bổ sung một số điều của Thông tư số 18/2026/TT-BTC ngày 05 tháng 3 năm 2026 của Bộ trưởng Bộ Tài chính quy định về hồ sơ, thủ tục quản lý thuế đối với hộ kinh doanh, cá nhân kinh doanh | F35: TT50_2026_BTC.pdf | G35: raw/VI. Ho kinh doanh ca nhan kinh doanh | H35: PDF scan (chụp hình) | I35: 20 | J35: 7 | K35: Có file | L35: https://datafiles.chinhphu.vn/cpp/files/vbpq/2026/5/50-btc.signed.pdf | N35: Máy scan (Smart Touch 1.9) | O35: Smart Touch 1.9 | P35: Kodak Alaris Inc. ; modified using iTextSharp™ 5.5.5 ©2000-2014 iText Group NV (AGPL-version) | Q35: 2026-05-15 | R35: Có
A36: 35 | B36: VII. Đăng ký doanh nghiệp | C36: 59/2020/QH14 | D36: Luật | E36: Luật Doanh nghiệp | F36: L59_2020_QH14.pdf + L59_2020_QH14_tiep.pdf | G36: raw/VII. Dang ky doanh nghiep | H36: PDF scan (chụp hình) | I36: 141 | J36: 2 | K36: Có file | L36: https://datafiles.chinhphu.vn/cpp/files/vbpq/2020/07/59.signed.pdf, https://datafiles.chinhphu.vn/cpp/files/vbpq/2020/07/59tiep.pdf | M36: Nguồn chia làm 2 phần: L59_2020_QH14.pdf + L59_2020_QH14_tiep.pdf | N36: Máy scan (Smart Touch 1.8) | O36: Smart Touch 1.8 | P36: Kodak Alaris Inc. ; modified using VGCA.Base 5.2.1 (c) 1T3XT BVBA | Q36: 2020-07-08 | R36: Có
A37: 36 | B37: VII. Đăng ký doanh nghiệp | C37: 03/2022/QH15 | D37: Luật | E37: Luật sửa đổi, bổ sung một số điều của Luật Đầu tư công, Luật Đầu tư theo phương thức đối tác công tư, Luật Đầu tư, Luật Nhà ở, Luật Đấu thầu, Luật Điện lực, Luật Doanh nghiệp, Luật Thuế tiêu thụ đặc biệt và Luật Thi hành án dân sự | F37: L03_2022_QH15.pdf | G37: raw/VII. Dang ky doanh nghiep | H37: PDF có text (xuất từ phần mềm khác) | I37: 15 | J37: 1768 | K37: Có file | L37: https://datafiles.chinhphu.vn/cpp/files/vbpq/2022/07/03-2022-qh15..pdf | N37: Không có metadata (thường là bản Công báo điện tử) | R37: Có
A38: 37 | B38: VII. Đăng ký doanh nghiệp | C38: 76/2025/QH15 | D38: Luật | E38: Luật sửa đổi, bổ sung một số điều của Luật Doanh nghiệp | F38: L76_2025_QH15.pdf | G38: raw/VII. Dang ky doanh nghiep | H38: PDF scan (chụp hình) | I38: 7 | J38: 21 | K38: Có file | L38: https://datafiles.chinhphu.vn/cpp/files/vbpq/2025/7/76qh.signed.pdf | N38: Máy scan (Smart Touch 1.9) | O38: Smart Touch 1.9 | P38: Kodak Alaris Inc. ; modified using iTextSharp™ 5.5.5 ©2000-2014 iText Group NV (AGPL-version) | Q38: 2025-07-16 | R38: Có
A39: 38 | B39: VII. Đăng ký doanh nghiệp | C39: 168/2025/NĐ-CP | D39: Nghị định | E39: Nghị định về đăng ký doanh nghiệp | F39: ND168_2025.pdf | G39: raw/VII. Dang ky doanh nghiep | H39: PDF scan (chụp hình) | I39: 122 | J39: 1 | K39: Có file | L39: https://datafiles.chinhphu.vn/cpp/files/vbpq/2025/7/168nd.signed.pdf | N39: Máy scan (Smart Touch 1.9) | O39: Smart Touch 1.9 | P39: Kodak Alaris Inc. ; modified using iTextSharp™ 5.5.5 ©2000-2014 iText Group NV (AGPL-version) | Q39: 2025-07-03 | R39: Có
A40: 39 | B40: VII. Đăng ký doanh nghiệp | C40: 296/2026/NĐ-CP | D40: Nghị định | E40: Nghị định sửa đổi, bổ sung một số điều của Nghị định số 168/2025/NĐ-CP ngày 30 tháng 6 năm 2025 của Chính phủ về đăng ký doanh nghiệp | F40: ND296_2026.pdf | G40: raw/VII. Dang ky doanh nghiep | H40: PDF scan (chụp hình) | I40: 14 | J40: 14 | K40: Có file | L40: https://datafiles.chinhphu.vn/cpp/files/vbpq/2026/7/296_2026_nd-cp_23072026-signed.signed.pdf | N40: Không rõ (VGCASignService 1.0.11 ©2014 VGCA - Ban Co yeu Chinh phu; modified using iTextSharp™ 5.5.5 ©2000-2014 iText Group NV (AGPL-version)) | P40: VGCASignService 1.0.11 ©2014 VGCA - Ban Co yeu Chinh phu; modified using iTextSharp™ 5.5.5 ©2000-2014 iText Group NV (AGPL-version) | Q40: 2026-07-24 | R40: Có
...

Sheet Tong hop
A1: Định dạng gốc | B1: Số văn bản | C1: Số trang
A2: PDF convert từ Word | B2: =COUNTIF('Danh muc van ban'!H2:H68,A2) -> 2 | C2: =SUMIF('Danh muc van ban'!H2:H68,A2,'Danh muc van ban'!I2:I68) -> 38
A3: PDF có text (xuất từ phần mềm khác) | B3: =COUNTIF('Danh muc van ban'!H2:H68,A3) -> 7 | C3: =SUMIF('Danh muc van ban'!H2:H68,A3,'Danh muc van ban'!I2:I68) -> 369
A4: PDF scan (chụp hình) | B4: =COUNTIF('Danh muc van ban'!H2:H68,A4) -> 57 | C4: =SUMIF('Danh muc van ban'!H2:H68,A4,'Danh muc van ban'!I2:I68) -> 3421
A5: Word gốc (.docx) | B5: =COUNTIF('Danh muc van ban'!H2:H68,A5) -> 0 | C5: =SUMIF('Danh muc van ban'!H2:H68,A5,'Danh muc van ban'!I2:I68) -> 0
A6: Word gốc (.doc) | B6: =COUNTIF('Danh muc van ban'!H2:H68,A6) -> 1 | C6: =SUMIF('Danh muc van ban'!H2:H68,A6,'Danh muc van ban'!I2:I68) -> 0
A7: Thiếu file | B7: =COUNTIF('Danh muc van ban'!K2:K68,"THIẾU FILE") -> 0
A8: Tổng số dòng danh mục | B8: =COUNTA('Danh muc van ban'!A2:A68) -> 67 | C8: =SUM(C2:C6) -> 3828
A10: Cách phân loại: trung bình < 200 ký tự chữ/trang -> PDF scan (chụp hình), phải OCR.
A11: Có text: nếu metadata Creator/Producer là Microsoft Word -> 'PDF convert từ Word', còn lại -> xuất từ phần mềm khác (vd Công báo).
A12: Metadata PDF scan ghi tên phần mềm máy scan (Kodak Smart Touch, HP Scan, IMIP Universal Scan...) -> xác nhận là bản chụp.
A13: Văn bản trùng (ND141/2026, TT152/2025) xuất hiện ở 2 nhóm nên được đếm 2 lần.

Sheet Thong ke token
A1: Document ID | B1: Số hiệu | C1: Loại VB | D1: Nguồn text | E1: Số trang | F1: Số Chương | G1: Số Mục | H1: Số Điều | I1: Số Khoản | J1: Số Điểm | K1: Số Phụ lục | L1: Có bảng | M1: Tổng token | N1: Token TB / Điều | O1: Token max / Điều | P1: P95 token / Điều | Q1: % Điều > 512 | R1: Token max / Khoản | S1: % Khoản > 512 | T1: Số unit độ tin cậy thấp | U1: Ngày ban hành | V1: Ngày hiệu lực | W1: Cảnh báo khi tách
A2: L108_2025_QH15 | B2: 108/2025/QH15 | C2: Luật | D2: OCR | E2: 65 | F2: 7 | G2: 9 | H2: 52 | I2: 265 | J2: 267 | K2: 0 | M2: 37489 | N2: 732 | O2: 3147 | P2: 2092 | Q2: 0.462 | R2: 1244 | S2: 0.049 | T2: 4 | U2: 2025-12-10 | V2: 2026-07-01 | W2: Điều 3: thiếu Khoản 1; Điều 12: thiếu Khoản 5; Chương OCR 'Chương H' -> suy ra Chương III
A3: ND252_2026 | B3: 252/2026/NĐ-CP | C3: Nghị định | D3: OCR | E3: 133 | F3: 5 | G3: 7 | H3: 76 | I3: 343 | J3: 533 | K3: 0 | M3: 78762 | N3: 1052 | O3: 2787 | P3: 2430 | Q3: 0.711 | R3: 1861 | S3: 0.082 | T3: 7 | U3: 2026-06-30 | V3: 2026-07-01 | W3: Điều 3: thiếu Khoản 6; Chương OCR '„ ChươngH i Ì' -> suy ra Chương II; Điều 10: thiếu Khoản 1
A4: ND255_2026 | B4: 255/2026/NĐ-CP | C4: Nghị định | D4: OCR | E4: 77 | F4: 4 | G4: 0 | H4: 23 | I4: 86 | J4: 97 | K4: 4 | L4: Có | M4: 39480 | N4: 909 | O4: 3344 | P4: 2863 | Q4: 0.696 | R4: 2676 | S4: 0.081 | T4: 4 | U4: 2026-06-30 | V4: 2026-07-01 | W4: Chương OCR 'Chương H' -> suy ra Chương II; Điều 6: thiếu Khoản 1; Điều 10: thiếu Khoản 1
A5: ND125_2020 | B5: 125/2020/NĐ-CP | C5: Nghị định | D5: OCR | E5: 87 | F5: 4 | G5: 2 | H5: 46 | I5: 187 | J5: 200 | K5: 12 | M5: 44325 | N5: 653 | O5: 7389 | P5: 1298 | Q5: 0.413 | R5: 4305 | S5: 0.037 | T5: 1 | U5: 2020-10-19 | V5: 2020-12-05 | W5: Chương OCR 'Chương H' -> suy ra Chương II; Nhảy từ Điều 28 sang Điều 30; Điều 30: thiếu Khoản 1
A6: ND310_2025 | B6: 310/2025/NĐ-CP | C6: Nghị định | D6: OCR | E6: 16 | F6: 0 | G6: 0 | H6: 4 | I6: 30 | J6: 19 | K6: 0 | M6: 9257 | N6: 2242 | O6: 8266 | P6: 7086 | Q6: 0.25 | R6: 1678 | S6: 0.167 | T6: 2 | U6: 2025-12-02 | V6: 2026-01-16 | W6: Điều 2: thiếu Khoản 2
A7: ND291_2026 | B7: 291/2026/NĐ-CP | C7: Nghị định | D7: OCR | E7: 3 | F7: 0 | G7: 1 | H7: 4 | I7: 6 | J7: 2 | K7: 0 | M7: 1103 | N7: 172 | O7: 438 | P7: 388 | Q7: 0 | R7: 184 | S7: 0 | T7: 0 | U7: 2026-07-21 | V7: 2026-07-21
A8: TT89_2026_BTC | B8: 89/2026/TT-BTC | C8: Thông tư | D8: OCR | E8: 839 | F8: 8 | G8: 6 | H8: 101 | I8: 358 | J8: 681 | K8: 352 | L8: Có | M8: 418722 | N8: 1233 | O8: 8225 | P8: 3612 | Q8: 0.673 | R8: 3086 | S8: 0.184 | T8: 6 | U8: 2026-06-30 | V8: 2026-07-01 | W8: Điều 15: thiếu Khoản 1; Điều 81: thiếu Khoản 1
A9: TT90_2026_BTC | B9: 90/2026/TT-BTC | C9: Thông tư | D9: OCR | E9: 196 | F9: 4 | G9: 10 | H9: 38 | I9: 143 | J9: 158 | K9: 44 | L9: Có | M9: 98146 | N9: 1216 | O9: 4437 | P9: 2814 | Q9: 0.658 | R9: 2813 | S9: 0.175 | T9: 3 | U9: 2026-06-30 | V9: 2026-07-01 | W9: Điều 23: thiếu Khoản 1; Điều 24: thiếu Khoản 2; Điều 38: thiếu Khoản 2
A10: ND254_2026 | B10: 254/2026/NĐ-CP | C10: Nghị định | D10: OCR | E10: 55 | F10: 4 | G10: 2 | H10: 45 | I10: 179 | J10: 155 | K10: 1 | M10: 31197 | N10: 589 | O10: 3327 | P10: 1347 | Q10: 0.356 | R10: 2962 | S10: 0.039 | T10: 2 | U10: 2026-06-30 | V10: 2026-07-01 | W10: Chương OCR '„ Chương H :' -> suy ra Chương II
A11: TT91_2026_BTC | B11: 91/2026/TT-BTC | C11: Thông tư | D11: OCR | E11: 97 | F11: 5 | G11: 0 | H11: 25 | I11: 77 | J11: 83 | K11: 28 | L11: Có | M11: 43564 | N11: 746 | O11: 3447 | P11: 2538 | Q11: 0.44 | R11: 1474 | S11: 0.104 | T11: 3 | U11: 2026-06-30 | V11: 2026-07-01 | W11: Điều 7: thiếu Khoản 2; Điều 8: thiếu Khoản 1; Chương OCR '! Ch1Ểoịng V' -> suy ra Chương V
A12: L48_2024_QH15 | B12: 48/2024/QH15 | C12: Luật | D12: Text | E12: 20 | F12: 4 | G12: 0 | H12: 18 | I12: 80 | J12: 85 | K12: 0 | M12: 10693 | N12: 603 | O12: 2389 | P12: 2161 | Q12: 0.333 | R12: 927 | S12: 0.05 | T12: 0 | U12: 2024-11-26 | V12: 2025-07-01
A13: L149_2025_QH15 | B13: 149/2025/QH15 | C13: Luật | D13: OCR | E13: 2 | F13: 0 | G13: 0 | H13: 2 | I13: 3 | J13: 2 | K13: 0 | M13: 664 | N13: 233 | O13: 406 | P13: 389 | Q13: 0 | R13: 291 | S13: 0 | T13: 1 | U13: 2025-12-11 | V13: 2026-01-01
A14: L09_2026_QH16 | B14: 09/2026/QH16 | C14: Luật | D14: OCR | E14: 2 | F14: 0 | G14: 0 | H14: 5 | I14: 2 | J14: 0 | K14: 0 | L14: Có | M14: 1260 | N14: 163 | O14: 315 | P14: 288 | Q14: 0 | R14: 72 | S14: 0 | T14: 0 | U14: 2026-04-24 | V14: 2026-04-24
A15: ND181_2025 | B15: 181/2025/NĐ-CP | C15: Nghị định | D15: OCR | E15: 75 | F15: 3 | G15: 4 | H15: 40 | I15: 129 | J15: 123 | K15: 4 | M15: 46270 | N15: 804 | O15: 3830 | P15: 2366 | Q15: 0.5 | R15: 3388 | S15: 0.047 | T15: 2 | U15: 2025-07-01 | V15: 2025-07-01 | W15: Điều 10: thiếu Khoản 1; Chương OCR ': Chương II c' -> suy ra Chương II; Chương OCR ': ChươngIV _' -> suy ra Chương III
A16: ND174_2025 | B16: 174/2025/NĐ-CP | C16: Nghị định | D16: OCR | E16: 56 | F16: 0 | G16: 0 | H16: 2 | I16: 10 | J16: 6 | K16: 5 | L16: Có | M16: 21588 | N16: 602 | O16: 954 | P16: 919 | Q16: 0.5 | R16: 279 | S16: 0 | T16: 0 | U16: 2025-06-30 | V16: 2025-07-01
A17: ND359_2025 | B17: 359/2025/NĐ-CP | C17: Nghị định | D17: OCR | E17: 3 | F17: 0 | G17: 0 | H17: 2 | I17: 5 | J17: 0 | K17: 0 | M17: 967 | N17: 340 | O17: 487 | P17: 472 | Q17: 0 | R17: 423 | S17: 0 | T17: 0 | U17: 2025-12-31 | V17: 2026-01-01
A18: ND144_2026 | B18: 144/2026/NĐ-CP | C18: Nghị định | D18: OCR | E18: 23 | F18: 0 | G18: 0 | H18: 6 | I18: 7 | J18: 0 | K18: 2 | M18: 13125 | N18: 222 | O18: 449 | P18: 419 | Q18: 0 | R18: 213 | S18: 0 | T18: 0 | U18: 2026-05-05 | V18: 2026-06-20
A19: TT69_2025_BTC | B19: 69/2025/TT-BTC | C19: Thông tư | D19: OCR | E19: 21 | F19: 0 | G19: 0 | H19: 10 | I19: 21 | J19: 45 | K19: 3 | M19: 12736 | N19: 816 | O19: 4221 | P19: 3098 | Q19: 0.3 | R19: 888 | S19: 0.333 | T19: 2 | U19: 2025-07-01 | V19: 2025-07-01 | W19: Điều 4: thiếu Khoản 1
A20: TT77_2025_BTC | B20: 77/2025/TT-BTC | C20: Thông tư | D20: OCR | E20: 3 | F20: 0 | G20: 0 | H20: 5 | I20: 13 | J20: 0 | K20: 0 | M20: 1053 | N20: 137 | O20: 379 | P20: 321 | Q20: 0 | R20: 227 | S20: 0 | T20: 0 | U20: 2025-07-30 | V20: 2025-07-30
A21: TT101_2025_BNNMT | B21: 101/2025/TT-BNNMT | C21: Thông tư | D21: Text | E21: 5 | F21: 0 | G21: 0 | H21: 4 | I21: 7 | J21: 0 | K21: 1 | L21: Có | M21: 2069 | N21: 110 | O21: 171 | P21: 160 | Q21: 0 | R21: 83 | S21: 0 | T21: 0 | U21: 2025-12-31 | V21: 2025-12-31
A22: L109_2025_QH15 | B22: 109/2025/QH15 | C22: Luật | D22: OCR | E22: 15 | F22: 4 | G22: 0 | H22: 29 | I22: 111 | J22: 54 | K22: 0 | M22: 7235 | N22: 253 | O22: 1006 | P22: 797 | Q22: 0.103 | R22: 288 | S22: 0 | T22: 0 | U22: 2025-12-10 | V22: 2026-07-01
A23: ND253_2026 | B23: 253/2026/NĐ-CP | C23: Nghị định | D23: OCR | E23: 61 | F23: 5 | G23: 5 | H23: 70 | I23: 227 | J23: 133 | K23: 1 | L23: Có | M23: 34003 | N23: 474 | O23: 3261 | P23: 1305 | Q23: 0.329 | R23: 1528 | S23: 0.04 | T23: 1 | U23: 2026-06-30 | V23: 2026-07-01 | W23: Điều 3: thiếu Khoản 1; Chương OCR 'Chương Y' -> suy ra Chương III; Nhảy từ Điều 28 sang Điều 30
A24: TT87_2026_BTC | B24: 87/2026/TT-BTC | C24: Thông tư | D24: OCR | E24: 6 | F24: 0 | G24: 0 | H24: 6 | I24: 21 | J24: 14 | K24: 0 | M24: 3450 | N24: 496 | O24: 1491 | P24: 1308 | Q24: 0.333 | R24: 547 | S24: 0.048 | T24: 0 | U24: 2026-06-30 | V24: 2026-07-01
A25: L67_2025_QH15 | B25: 67/2025/QH15 | C25: Luật | D25: OCR | E25: 21 | F25: 2 | G25: 0 | H25: 20 | I25: 81 | J25: 80 | K25: 0 | M25: 11934 | N25: 599 | O25: 1849 | P25: 1630 | Q25: 0.45 | R25: 1269 | S25: 0.037 | T25: 4 | U25: 2025-06-14 | V25: 2025-10-01 | W25: Điều 3: thiếu Khoản 5; Điều 4: thiếu Khoản 1; Chương OCR 'Chương H' -> suy ra Chương I
A26: ND320_2025 | B26: 320/2025/NĐ-CP | C26: Nghị định | D26: OCR | E26: 76 | F26: 2 | G26: 0 | H26: 26 | I26: 137 | J26: 211 | K26: 0 | M26: 45224 | N26: 1751 | O26: 8408 | P26: 4070 | Q26: 0.731 | R26: 3194 | S26: 0.153 | T26: 2 | U26: 2025-12-15 | V26: 2025-12-15 | W26: Chương OCR 'Chương IV i :' -> suy ra Chương II; Điều 25: thiếu Khoản 3
A27: ND20_2026 | B27: 20/2026/NĐ-CP | C27: Nghị định | D27: OCR | E27: 23 | F27: 5 | G27: 0 | H27: 17 | I27: 61 | J27: 51 | K27: 1 | L27: Có | M27: 11340 | N27: 533 | O27: 2194 | P27: 1467 | Q27: 0.294 | R27: 502 | S27: 0 | T27: 2 | U27: 2026-01-15 | V27: 2026-01-15 | W27: Điều 3: thiếu Khoản 1
A28: ND141_2026 | B28: 141/2026/NĐ-CP | C28: Nghị định | D28: OCR | E28: 4 | F28: 0 | G28: 0 | H28: 5 | I28: 5 | J28: 4 | K28: 0 | M28: 2266 | N28: 336 | O28: 513 | P28: 508 | Q28: 0.2 | R28: 380 | S28: 0 | T28: 0 | U28: 2026-04-29 | V28: 2026-01-01
A29: ND245_2026 | B29: 245/2026/NĐ-CP | C29: Nghị định | D29: OCR | E29: 11 | F29: 0 | G29: 0 | H29: 5 | I29: 17 | J29: 10 | K29: 0 | M29: 5327 | N29: 1023 | O29: 2888 | P29: 2504 | Q29: 0.6 | R29: 2416 | S29: 0.059 | T29: 0 | U29: 2026-06-27 | V29: 2026-06-27
A30: TT20_2026_BTC | B30: 20/2026/TT-BTC | C30: Thông tư | D30: OCR | E30: 22 | F30: 0 | G30: 0 | H30: 10 | I30: 40 | J30: 80 | K30: 2 | M30: 13636 | N30: 1248 | O30: 4576 | P30: 4529 | Q30: 0.3 | R30: 1596 | S30: 0.2 | T30: 3 | U30: 2026-03-12 | V30: 2026-03-12 | W30: Điều 1: thiếu Khoản 1; Điều 1: thiếu Khoản 3; Điều 3: thiếu Khoản 11
A31: ND68_2026 | B31: 68/2026/NĐ-CP | C31: Nghị định | D31: OCR | E31: 19 | F31: 2 | G31: 0 | H31: 19 | I31: 62 | J31: 60 | K31: 0 | M31: 11043 | N31: 576 | O31: 2724 | P31: 1253 | Q31: 0.474 | R31: 823 | S31: 0.048 | T31: 0 | U31: 2026-03-05 | V31: 2026-03-05 | W31: Chương OCR '“Chương H' -> suy ra Chương II
A32: TT152_2025_BTC | B32: 152/2025/TT-BTC | C32: Thông tư | D32: OCR | E32: 14 | F32: 4 | G32: 3 | H32: 8 | I32: 20 | J32: 10 | K32: 0 | L32: Có | M32: 5835 | N32: 675 | O32: 2751 | P32: 2063 | Q32: 0.375 | R32: 2289 | S32: 0.05 | T32: 0 | U32: 2025-12-31 | V32: 2026-01-01 | W32: Chương OCR 'Chứng từ' -> suy ra Chương IV; Chương OCR 'Chứng từ' -> suy ra Chương V; Chương OCR 'Chứng từ' -> suy ra Chương VI
A33: TT18_2026_BTC | B33: 18/2026/TT-BTC | C33: Thông tư | D33: OCR | E33: 44 | F33: 0 | G33: 0 | H33: 9 | I33: 20 | J33: 6 | K33: 21 | L33: Có | M33: 17056 | N33: 275 | O33: 1070 | P33: 759 | Q33: 0.111 | R33: 568 | S33: 0.05 | T33: 0 | U33: 2026-03-05 | V33: 2026-03-05
A34: TT50_2026_BTC | B34: 50/2026/TT-BTC | C34: Thông tư | D34: OCR | E34: 20 | F34: 0 | G34: 0 | H34: 4 | I34: 3 | J34: 0 | K34: 6 | L34: Có | M34: 7489 | N34: 134 | O34: 189 | P34: 181 | Q34: 0 | R34: 118 | S34: 0 | T34: 0 | U34: 2026-05-13 | V34: 2026-05-13
A35: L59_2020_QH14 | B35: 59/2020/QH14 | C35: Luật | D35: OCR | E35: 141 | F35: 8 | G35: 2 | H35: 216 | I35: 860 | J35: 547 | K35: 0 | M35: 83481 | N35: 395 | O35: 1838 | P35: 852 | Q35: 0.218 | R35: 659 | S35: 0.001 | T35: 36 | U35: 2020-06-17 | V35: 2021-01-01 | W35: Điều 4: thiếu Khoản 11; Điều 5: thiếu Khoản 1; Điều 14: thiếu Khoản 1
A36: L03_2022_QH15 | B36: 03/2022/QH15 | C36: Luật | D36: Text | E36: 15 | F36: 0 | G36: 0 | H36: 11 | I36: 28 | J36: 7 | K36: 0 | L36: Có | M36: 6752 | N36: 565 | O36: 1883 | P36: 1424 | Q36: 0.455 | R36: 1075 | S36: 0.036 | T36: 0 | U36: 2022-01-11 | V36: 2022-03-01
A37: L76_2025_QH15 | B37: 76/2025/QH15 | C37: Luật | D37: OCR | E37: 7 | F37: 0 | G37: 0 | H37: 3 | I37: 29 | J37: 19 | K37: 0 | M37: 4062 | N37: 1279 | O37: 3571 | P37: 3238 | Q37: 0.333 | R37: 463 | S37: 0 | T37: 1 | U37: 2025-06-17 | V37: 2025-07-01 | W37: Điều 1: thiếu Khoản 2
A38: ND168_2025 | B38: 168/2025/NĐ-CP | C38: Nghị định | D38: OCR | E38: 122 | F38: 7 | G38: 0 | H38: 120 | I38: 479 | J38: 299 | K38: 0 | M38: 69777 | N38: 587 | O38: 2602 | P38: 1735 | Q38: 0.417 | R38: 1478 | S38: 0.023 | T38: 10 | U38: 2025-06-30 | V38: 2025-07-01 | W38: Điều 3: thiếu Khoản 5; Điều 10: thiếu Khoản 1; Điều 20: thiếu Khoản 1
A39: ND296_2026 | B39: 296/2026/NĐ-CP | C39: Nghị định | D39: OCR | E39: 14 | F39: 0 | G39: 0 | H39: 22 | I39: 44 | J39: 15 | K39: 0 | M39: 8003 | N39: 355 | O39: 776 | P39: 771 | Q39: 0.273 | R39: 630 | S39: 0.068 | T39: 1 | U39: 2026-07-23 | V39: 2026-07-23 | W39: Điều 19: thiếu Khoản 4
A40: TT68_2025_BTC | B40: 68/2025/TT-BTC | C40: Thông tư | D40: OCR | E40: 266 | F40: 0 | G40: 0 | H40: 3 | I40: 8 | J40: 2 | K40: 165 | L40: Có | M40: 123406 | N40: 141 | O40: 284 | P40: 263 | Q40: 0 | R40: 122 | S40: 0 | T40: 5 | U40: 2025-07-01 | V40: 2025-07-01
...

Sheet Phan bo token
A1: Khoảng token | B1: Số Điều | C1: % Điều | D1: Số Khoản | E1: % Khoản
A2: 1–128 | B2: 358 | C2: =B2/SUM(B$2:B$8) -> 0.15331906 | D2: 5798 | E2: =D2/SUM(D$2:D$8) -> 0.70074934
A3: 129–256 | B3: 557 | C3: =B3/SUM(B$2:B$8) -> 0.2385439 | D3: 1435 | E3: =D3/SUM(D$2:D$8) -> 0.17343486
A4: 257–512 | B4: 683 | C4: =B4/SUM(B$2:B$8) -> 0.29250535 | D4: 686 | E4: =D4/SUM(D$2:D$8) -> 0.082910321
A5: 513–1024 | B5: 442 | C5: =B5/SUM(B$2:B$8) -> 0.18929336 | D5: 244 | E5: =D5/SUM(D$2:D$8) -> 0.029489969
A6: 1025–2048 | B6: 199 | C6: =B6/SUM(B$2:B$8) -> 0.085224839 | D6: 82 | E6: =D6/SUM(D$2:D$8) -> 0.0099105632
A7: 2049–4096 | B7: 79 | C7: =B7/SUM(B$2:B$8) -> 0.033832976 | D7: 23 | E7: =D7/SUM(D$2:D$8) -> 0.0027797921
A8: > 4096 | B8: 17 | C8: =B8/SUM(B$2:B$8) -> 0.0072805139 | D8: 6 | E8: =D8/SUM(D$2:D$8) -> 0.00072516316
A9: Tổng | B9: =SUM(B2:B8) -> 2335 | D9: =SUM(D2:D8) -> 8274
A11: Thống kê | B11: Điều | D11: Khoản
A12: Trung bình | B12: 581 | D12: 152
A13: Trung vị (P50) | B13: 333 | D13: 75
A14: P90 | B14: 1194 | D14: 300
A15: P95 | B15: 1848 | D15: 463
A16: Lớn nhất | B16: 35264 | D16: 29355

Sheet Metadata van ban
A1: Document ID | B1: Số hiệu | C1: Loại VB | D1: Tên văn bản (trích từ văn bản) | E1: Cơ quan ban hành | F1: Ngày ban hành | G1: Nguồn ngày ban hành | H1: Ngày hiệu lực | I1: Nguồn ngày hiệu lực | J1: Câu làm bằng chứng hiệu lực | K1: Trạng thái | L1: Sửa đổi VB | M1: Thay thế VB | N1: Hướng dẫn VB | O1: Bị sửa đổi bởi | P1: Bị thay thế bởi | Q1: Được hướng dẫn bởi | R1: Định dạng gốc | S1: Cách lấy text | T1: OCR engine | U1: OCR DPI | V1: OCR độ tin cậy TB (0-100) | W1: OCR % từ tin cậy thấp (<60) | X1: Thời gian xử lý (giây)
A2: L108_2025_QH15 | B2: 108/2025/QH15 | C2: Luật | D2: Luật Quản lý thuế | E2: Quốc hội | F2: 2025-12-10 | G2: đối chiếu bản gốc: Trang 65 bản gốc: "Luật này được Quốc hội ... thông qua ngày 10 tháng 12 năm 2025" | H2: 2026-07-01 | I2: đối chiếu bản gốc: Trang 65 bản gốc, Điều 52 khoản 1: hiệu lực từ 01/7/2026 (Điều 13, Điều 26 hiệu lực từ 01/01/2026) | J2: khoán thi hành Ị 1. Luật này có hiệu lưc thi ủmh từ ngày 01 tháng 7 năm 2026 | K2: active | M2: 38/2019/QH14 | Q2: 252/2026/NĐ-CP, 255/2026/NĐ-CP, 89/2026/TT-BTC, 254/2026/NĐ-CP, 91/2026/TT-BTC | R2: PDF scan (chụp hình) | S2: OCR | T2: Tesseract 5 (LSTM), ngôn ngữ vie | U2: 200 | V2: 89.9 | W2: 0.0292 | X2: 135
A3: ND252_2026 | B3: 252/2026/NĐ-CP | C3: Nghị định | D3: NGHỊ ĐỊNH Quy định chỉ tiết một số điều và biện pháp đễ to chuc, hướng dẫn thi hành Luật Quản lý thuế | E3: Chính phủ | F3: 2026-06-30 | G3: đối chiếu trang 1 bản gốc | H3: 2026-07-01 | I3: tự động (regex) | J3: G 132>>> 132 1. Nghị định này có hiệu lực thi hành kề từ ngày 01 tháng 7 năm 2026 | K3: active | M3: 126/2020/NĐ-CP | N3: 108/2025/QH15 | Q3: 89/2026/TT-BTC | R3: PDF scan (chụp hình) | S3: OCR | T3: Tesseract 5 (LSTM), ngôn ngữ vie | U3: 200 | V3: 90.1 | W3: 0.0257 | X3: 285
A4: ND255_2026 | B4: 255/2026/NĐ-CP | C4: Nghị định | D4: NGHỊ ĐỊNH Quy định về quản lý thuế đối với các giao dịch liên kết của những doanh nghiệp có quan hệ liên kết | E4: Chính phủ | F4: 2026-06-30 | G4: đối chiếu trang 1 bản gốc | H4: 2026-07-01 | I4: tự động (regex) | J4: lực thi hành Ì. Nghị định này có hiệu lực thi hành từ ngày 01 tháng 7 năm 2026 | K4: active | M4: 132/2020/NĐ-CP | N4: 108/2025/QH15 | R4: PDF scan (chụp hình) | S4: OCR | T4: Tesseract 5 (LSTM), ngôn ngữ vie | U4: 200 | V4: 88.5 | W4: 0.0462 | X4: 142
A5: ND125_2020 | B5: 125/2020/NĐ-CP | C5: Nghị định | D5: NGHỊ ĐỊNH Căn cứ Luật Tổ chức Chính phủ ngày 19 tháng 6 năm 2015; | E5: Chính phủ | F5: 2020-10-19 | G5: đối chiếu trang 1 bản gốc | H5: 2020-12-05 | I5: tự động (regex) | J5: lực thi hành 1. Nghị định này có hiệu lực thị hành từ ngày 05 tháng 12 năm 2020 | K5: active | O5: 310/2025/NĐ-CP, 291/2026/NĐ-CP | R5: PDF scan (chụp hình) | S5: OCR | T5: Tesseract 5 (LSTM), ngôn ngữ vie | U5: 200 | V5: 83.3 | W5: 0.1116 | X5: 162
A6: ND310_2025 | B6: 310/2025/NĐ-CP | C6: Nghị định | D6: NGHỊ ĐỊNH Sửa đồi, bồ sung một số điều của Nghị định số 125/2020/NĐ-CP vx Điện TỪ HÍMAPH) Ì1gzìy 19 tháng 10 năm 2020 của Chmh phu quy định xử phạt vi phạm hành chính về thuế, hóa đơn mìuewms M.ụe | E6: Chính phủ | F6: 2025-12-02 | G6: đối chiếu trang 1 bản gốc | H6: 2026-01-16 | I6: tự động (regex) | J6: iệm thi hành 1. Nghị định này có hiệu lực thì hành từ ngày 16 tháng 01 năm 2026 | K6: active | L6: 125/2020/NĐ-CP | O6: 291/2026/NĐ-CP | R6: PDF scan (chụp hình) | S6: OCR | T6: Tesseract 5 (LSTM), ngôn ngữ vie | U6: 200 | V6: 89.6 | W6: 0.0317 | X6: 32
A7: ND291_2026 | B7: 291/2026/NĐ-CP | C7: Nghị định | D7: NGHỊ ĐỊNH Sửa đổi, bố sung một số điều của Nghị định số 125/2020/NĐ-CP ngày 19 tháng 10 năm 2020 của Chính phủ quy định xử phạt vi phạm hành chính về thuế, hóa đơn được sửa đổi, bồ sung bởi Nghị định số 102/2021/NĐ-CP ngày 16 tháng 11 năm 2021 của Chính phủ và Nghị định số 310/2025/NĐ-CP ngày 02 tháng 12 năm 2025 của Chính phủ | E7: Chính phủ | F7: 2026-07-21 | G7: đối chiếu trang 1 bản gốc | H7: 2026-07-21 | I7: tự động (regex) | J7: oản thi hành 1. Nghị định này có hiệu lực thi hành kể từ ngày ký | K7: active | L7: 125/2020/NĐ-CP, 102/2021/NĐ-CP, 310/2025/NĐ-CP | R7: PDF scan (chụp hình) | S7: OCR | T7: Tesseract 5 (LSTM), ngôn ngữ vie | U7: 200 | V7: 88.9 | W7: 0.0429 | X7: 5
A8: TT89_2026_BTC | B8: 89/2026/TT-BTC | C8: Thông tư | D8: THÔNG TƯ Quy định chỉ tiết một số điều của Luật Quản lý thuế và Nghị định số 252/2026/NĐ-CP của Chính phủ quy định chỉ tiết một số điều và biện pháp để tổ chức, hướng dẫn thi hành Luật Quản lý thuế | E8: Bộ Tài chính | F8: 2026-06-30 | G8: đối chiếu trang 1 bản gốc | H8: 2026-07-01 | I8: tự động (regex) | J8: lực thi hành 1. Thông tư này có hiệu lực thi hành từ ngày 01 tháng 7 năm 2026 | K8: active | N8: 108/2025/QH15, 252/2026/NĐ-CP | R8: PDF scan (chụp hình) | S8: OCR | T8: Tesseract 5 (LSTM), ngôn ngữ vie | U8: 200 | V8: 83.8 | W8: 0.0926 | X8: 1416
A9: TT90_2026_BTC | B9: 90/2026/TT-BTC | C9: Thông tư | D9: THÔNG TƯ Quy định về đăng ký thuế | E9: Bộ Tài chính | F9: 2026-06-30 | G9: đối chiếu trang 1 bản gốc | H9: 2026-07-01 | I9: tự động (regex) | J9: u lực thi hành 1. Thông tư mỵ có hiệu lực thị hành kể từ ngày 01 tháng 7 năm 2026 | K9: active | M9: 86/2024/TT-BTC | R9: PDF scan (chụp hình) | S9: OCR | T9: Tesseract 5 (LSTM), ngôn ngữ vie | U9: 200 | V9: 88 | W9: 0.0518 | X9: 339
A10: ND254_2026 | B10: 254/2026/NĐ-CP | C10: Nghị định | D10: NGHỊ ĐỊNH Quy định chỉ tiết một số điều và biện pháp đề tô chức, hướng dẫn thi hành Luật Quản lý thuế số 108/2025/QH15 về hóa đơn điện tử, chứng từ điện tử | E10: Chính phủ | F10: 2026-06-30 | G10: đối chiếu trang 1 bản gốc | H10: 2026-07-01 | I10: tự động (regex) | J10: lực thi hành 1. Nghị định này có hiệu lực thi hành từ ngày 01 tháng 7 năm 2026 | K10: active | M10: 123/2020/NĐ-CP, 70/2025/NĐ-CP | N10: 108/2025/QH15 | Q10: 91/2026/TT-BTC | R10: PDF scan (chụp hình) | S10: OCR | T10: Tesseract 5 (LSTM), ngôn ngữ vie | U10: 200 | V10: 90 | W10: 0.0266 | X10: 111
A11: TT91_2026_BTC | B11: 91/2026/TT-BTC | C11: Thông tư | D11: THÔNG TƯ Quy định một số điều của Luật Quần lý fflue và Ngh1 ổnh số 254/2026/NĐ- CP của Chính phủ quy định chỉ tiết một số điều m biện ¬pháp để tổ chức, hướng dẫn thi hành Luật Quản lý thuế số 108/2025/QH15 về hóa đơn điện tử, chứng từ điện tứ lìẦ N9ay _2rẹtT’ỈĨ’lẵffJ›Z.Ế | E11: Bộ Tài chính | F11: 2026-06-30 | G11: đối chiếu trang 1 bản gốc | H11: 2026-07-01 | I11: tự động (regex) | J11: tổ chức cung 1. Thông tư này có hiệu lực thi hành kể từ ngày 01 tháng 7 năm 2026 | K11: active | M11: 32/2025/TT-BTC | N11: 108/2025/QH15, 254/2026/NĐ-CP | R11: PDF scan (chụp hình) | S11: OCR | T11: Tesseract 5 (LSTM), ngôn ngữ vie | U11: 200 | V11: 86.4 | W11: 0.0692 | X11: 161
A12: L48_2024_QH15 | B12: 48/2024/QH15 | C12: Luật | D12: LUẬT THUẾ GIÁ TRỊ GIA TĂNG | E12: Quốc hội | F12: 2024-11-26 | G12: tự động (regex) | H12: 2025-07-01 | I12: tự động (regex) | J12: Hiệu lực thi hành 1. Luật này có hiệu lực thi hành từ ngày 01 tháng 7 năm 2025 | K12: active | M12: 13/2008/QH12 | O12: 149/2025/QH15, 09/2026/QH16 | Q12: 181/2025/NĐ-CP, 69/2025/TT-BTC | R12: PDF có text (xuất từ phần mềm khác) | S12: PDF text layer | X12: 0
A13: L149_2025_QH15 | B13: 149/2025/QH15 | C13: Luật | D13: LUẬT SỬA ĐỎI, BỎ SUNG MỘT SÓ ĐIỀU wA LUAT THUE GIÁ TRỊ GIA TĂNG | E13: Quốc hội | F13: 2025-12-11 | G13: đối chiếu bản gốc: Trang 2 bản gốc: thông qua ngày 11 tháng 12 năm 2025 | H13: 2026-01-01 | I13: tự động (regex) | J13: 2. Hiệu lực thi hành Luật này có hiệu lực thi hành từ ngày 01 tháng 01 năm 2026 | K13: active | L13: 48/2024/QH15 | R13: PDF scan (chụp hình) | S13: OCR | T13: Tesseract 5 (LSTM), ngôn ngữ vie | U13: 200 | V13: 88.1 | W13: 0.0454 | X13: 3
A14: L09_2026_QH16 | B14: 09/2026/QH16 | C14: Luật | D14: LUẬT SỬA ĐÔI, BỎ SUNG MỘT SÓ ĐIỀU CỦA LUẬT THUÊ THU NHẬP CÁ NHÂN, LUẬT THUÊ GIÁ TRỊ GIA TĂNG, LUẬT THUÊ THU NHẬP DOANH NGHIỆP VÀ LUẬT THUÊ TIÊU THỤ ĐẶC BIỆT | E14: Quốc hội | F14: 2026-04-24 | G14: tự động (regex) | H14: 2026-04-24 | I14: tự động (regex) | J14: Hiệu lực thi hành 1. Luật này có hiệu lực thi hành từ ngày được thông qua | K14: active | L14: 48/2024/QH15, 109/2025/QH15, 67/2025/QH15 | R14: PDF scan (chụp hình) | S14: OCR | T14: Tesseract 5 (LSTM), ngôn ngữ vie | U14: 200 | V14: 86.8 | W14: 0.0623 | X14: 5
A15: ND181_2025 | B15: 181/2025/NĐ-CP | C15: Nghị định | D15: NGHỊ ĐỊNH uy định chỉ tiết thi hành một số điều của Luật Thuế giá trị gia tăng | E15: Chính phủ | F15: 2025-07-01 | G15: đối chiếu bản gốc: Trang 1 bản gốc: Hà Nội, ngày 01 tháng 7 năm 2025 | H15: 2025-07-01 | I15: tự động (regex) | J15: lực thi hành 1. Nghị định này có hiệu lực thi hành từ ngày 01 tháng 7 năm 2025 | K15: active | M15: 209/2013/NĐ-CP | N15: 48/2024/QH15 | O15: 359/2025/NĐ-CP, 144/2026/NĐ-CP | Q15: 69/2025/TT-BTC, 77/2025/TT-BTC, 101/2025/TT-BNNMT | R15: PDF scan (chụp hình) | S15: OCR | T15: Tesseract 5 (LSTM), ngôn ngữ vie | U15: 200 | V15: 88.5 | W15: 0.0415 | X15: 160
A16: ND174_2025 | B16: 174/2025/NĐ-CP | C16: Nghị định | D16: NGHỊ ĐỊNH định chính sách giảm thuê giá trị gia tăng theo Nghị quyết số 204/2025/QH15 ngày 17 tháng 6 năm 2025 của Quốc hội | E16: Chính phủ | F16: 2025-06-30 | G16: đối chiếu bản gốc: Trang 1 bản gốc: Hà Nội, ngày 30 tháng 6 năm 2025 | H16: 2025-07-01 | I16: tự động (regex) | J16: oản thi hành 1. Nghị định này có hiệu lực thi hành từ ngày 01 tháng 7 năm 2025 | K16: active | R16: PDF scan (chụp hình) | S16: OCR | T16: Tesseract 5 (LSTM), ngôn ngữ vie | U16: 200 | V16: 86.3 | W16: 0.0761 | X16: 92
A17: ND359_2025 | B17: 359/2025/NĐ-CP | C17: Nghị định | D17: NGHỊ ĐỊNH Sửa đổi, bỗ sung một số điều của Nghị định số 181/2025/NĐ-CP ngày 01 tháng 7 năm 2025 của Chính phủ quy định chỉ tiết thi hành một số điều của Luật Thuế giá trị gia tăng | E17: Chính phủ | F17: 2025-12-31 | G17: đối chiếu trang 1 bản gốc | H17: 2026-01-01 | I17: tự động (regex) | J17: oản thị hành 1. Nghị định này có hiệu lực thi hành từ ngày 01 tháng 01 năm 2026 | K17: active | L17: 181/2025/NĐ-CP | O17: 144/2026/NĐ-CP | R17: PDF scan (chụp hình) | S17: OCR | T17: Tesseract 5 (LSTM), ngôn ngữ vie | U17: 200 | V17: 89.5 | W17: 0.0328 | X17: 4
A18: ND144_2026 | B18: 144/2026/NĐ-CP | C18: Nghị định | D18: NGHỊ ĐỊNH ' Sll’8 đon, bồ sung một số điều của Nghị định số 181/2025/NĐ-CP ưay 01 tháng 7 năm 2025 của Chính phú quy định chỉ tiết thi hành mot số điều của Luật Thue giá trị gia tăng đã được sửa đổi, bỗ sung một số điều bởi Nghị định số 359/2025/NĐ-CP ngày 31 tháng 12 năm 2025 của Chính phủ | E18: Chính phủ | F18: 2026-05-05 | G18: đối chiếu trang 1 bản gốc | H18: 2026-06-20 | I18: tự động (regex) | J18: oản thi hành 1. Nghị định này có hiệu lực thi hành kế từ ngày 20 tháng 6 năm 2026 | K18: active | L18: 181/2025/NĐ-CP, 359/2025/NĐ-CP | R18: PDF scan (chụp hình) | S18: OCR | T18: Tesseract 5 (LSTM), ngôn ngữ vie | U18: 200 | V18: 83 | W18: 0.1237 | X18: 45
A19: TT69_2025_BTC | B19: 69/2025/TT-BTC | C19: Thông tư | D19: Thông tư quy định chi tiết một số điều của Luật Thuế giá trị gia tăng và hướng dẫn thực hiện Nghị định số 181/2025/NĐ-CP ngày 01 tháng 7 năm 2025 của Chính phủ quy định chi tiết thi hành một số điều của Luật Thuế giá trị gia tăng | E19: Bộ Tài chính | F19: 2025-07-01 | G19: đối chiếu trang 1 bản gốc | H19: 2025-07-01 | I19: tự động (regex) | J19: lực thi hành 1. Thông tư này có hiệu lực thi hành từ ngày 01 tháng 7 năm 2025 | K19: active | M19: 219/2013/TT-BTC | N19: 48/2024/QH15, 181/2025/NĐ-CP | R19: PDF scan (chụp hình) | S19: OCR | T19: Tesseract 5 (LSTM), ngôn ngữ vie | U19: 200 | V19: 89.9 | W19: 0.0237 | X19: 52
A20: TT77_2025_BTC | B20: 77/2025/TT-BTC | C20: Thông tư | D20: THÔNG TƯ Quy định chi tiết các dịch vụ kinh doanh chứng khoán và chuyên nhượng chứng khoán theo Nghị định số 181/2025/NĐ CPngày0l mang 7 năm 2025 của Chính phú quy định chi tiết thi hành một số điều của Luật Thuế giá trị gia tăng | E20: Bộ Tài chính | F20: 2025-07-30 | G20: đối chiếu trang 1 bản gốc | H20: 2025-07-30 | I20: tự động (regex) | J20: lực thi hành 1. Thông tư này có hiệu lực thi hành kể từ ngày 30 tháng 7 năm 2025 | K20: active | N20: 181/2025/NĐ-CP | R20: PDF scan (chụp hình) | S20: OCR | T20: Tesseract 5 (LSTM), ngôn ngữ vie | U20: 200 | V20: 90.1 | W20: 0.0213 | X20: 5
A21: TT101_2025_BNNMT | B21: 101/2025/TT-BNNMT | C21: Thông tư | D21: THÔNG TƯ Hướng dẫn các loại máy chuyên dùng khác phục vụ cho sản xuất nông nghiệp chưa được quy định tại khoản 6 Điều 19 Nghị định số 181/2025/NĐ-CP ngày 01 tháng 7 năm 2025 của Chính phủ quy định chi tiết thi hành một số điều của Luật Thuế giá trị gia tăng | E21: Bộ Nông nghiệp và Môi trường | F21: 2025-12-31 | G21: đối chiếu bản gốc: Trang 1 bản gốc: số 101 và ngày 31/12/2025 được điền tay trên bản PDF (lớp chữ để trống) | H21: 2025-12-31 | I21: đối chiếu bản gốc: Điều 4: hiệu lực kể từ ngày ký ban hành (31/12/2025) | J21: lực thi hành 1. Thông tư này có hiệu lực thi hành kể từ ngày ký | K21: active | N21: 181/2025/NĐ-CP | R21: PDF convert từ Word | S21: PDF text layer | X21: 0
A22: L109_2025_QH15 | B22: 109/2025/QH15 | C22: Luật | D22: LUẬT U THUFÊ THU NHẬP CÁ NHẮN | E22: Quốc hội | F22: 2025-12-10 | G22: tự động (regex) | H22: 2026-07-01 | I22: tự động (regex) | J22: Hiệu lực thi hành 1. Luật này có hiệu lực thị hành từ ngày 01 tháng 7 năm 2026 | K22: active | M22: 04/2007/QH12 | O22: 09/2026/QH16 | Q22: 253/2026/NĐ-CP, 87/2026/TT-BTC | R22: PDF scan (chụp hình) | S22: OCR | T22: Tesseract 5 (LSTM), ngôn ngữ vie | U22: 200 | V22: 90.9 | W22: 0.0145 | X22: 31
A23: ND253_2026 | B23: 253/2026/NĐ-CP | C23: Nghị định | D23: NGHỊ ĐỊNH - Quy định chỉ tiết một số điều và biện pháp để tô chức, hướng dẫn thi hành Luật Thuế thu nhập cá nhân | E23: Chính phủ | F23: 2026-06-30 | G23: đối chiếu trang 1 bản gốc | H23: 2026-07-01 | I23: tự động (regex) | J23: lực thi hành 1. Nghị định này có hiệu lực thi hành từ ngày 01 tháng 7 năm 2026 | K23: active | N23: 109/2025/QH15 | Q23: 87/2026/TT-BTC | R23: PDF scan (chụp hình) | S23: OCR | T23: Tesseract 5 (LSTM), ngôn ngữ vie | U23: 200 | V23: 90.2 | W23: 0.0221 | X23: 132
A24: TT87_2026_BTC | B24: 87/2026/TT-BTC | C24: Thông tư | D24: THÔNG TƯ QuẮv định chỉ tiết một số điều của Luật Thuế thu nhập cá nhan và Nghị định sô B3/2026/NĐ-CP của Chính phủ quy định chỉ tiết một số điều và biện pháp đề tổ chức, hướng dẫn thi hành Luật Thuế thu nhập cá nhân | E24: Bộ Tài chính | F24: 2026-06-30 | G24: đối chiếu trang 1 bản gốc | H24: 2026-07-01 | I24: tự động (regex) | J24: lực thi hành 1. Thông tư này có hiệu lực thi hành từ ngày 01 tháng 7 năm 2026 | K24: active | M24: 111/2013/TT-BTC | N24: 109/2025/QH15, 253/2026/NĐ-CP | R24: PDF scan (chụp hình) | S24: OCR | T24: Tesseract 5 (LSTM), ngôn ngữ vie | U24: 200 | V24: 89.9 | W24: 0.0328 | X24: 15
A25: L67_2025_QH15 | B25: 67/2025/QH15 | C25: Luật | D25: LUẬT _ THUÊ THU NHẬP DOANH NGHIỆP | E25: Quốc hội | F25: 2025-06-14 | G25: tự động (regex) | H25: 2025-10-01 | I25: tự động (regex) | J25: Hiệu lực thi hành 1. Luật nay có hiệu lực thi hành từ ngày 01 tháng 10 năm 2025 | K25: active | M25: 14/2008/QH12 | O25: 09/2026/QH16 | Q25: 320/2025/NĐ-CP, 20/2026/TT-BTC | R25: PDF scan (chụp hình) | S25: OCR | T25: Tesseract 5 (LSTM), ngôn ngữ vie | U25: 200 | V25: 90.4 | W25: 0.0227 | X25: 44
A26: ND320_2025 | B26: 320/2025/NĐ-CP | C26: Nghị định | D26: NGHỊ ĐỊNH 5.Í Quy định chỉ tiết một số điều và biện pháp để tổ chức, hướng dẫn thi hành Luật Thuế thu nhập doanh nghiệp | E26: Chính phủ | F26: 2025-12-15 | G26: đối chiếu bản gốc: Trang 1 bản gốc: Hà Nội, ngày 15 tháng 12 năm 2025 | H26: 2025-12-15 | I26: đối chiếu bản gốc: Điều 24 khoản 1: hiệu lực kể từ ngày ký ban hành, áp dụng từ kỳ tính thuế TNDN năm 2025 | J26: lực thi hành 1. Nghị định này có hiệu lực thi hành kế từ ngày ký | K26: active | M26: 218/2013/NĐ-CP | N26: 67/2025/QH15 | O26: 141/2026/NĐ-CP | Q26: 20/2026/TT-BTC | R26: PDF scan (chụp hình) | S26: OCR | T26: Tesseract 5 (LSTM), ngôn ngữ vie | U26: 200 | V26: 90 | W26: 0.0231 | X26: 164
A27: ND20_2026 | B27: 20/2026/NĐ-CP | C27: Nghị định | D27: NGHỊ ĐỊNH Ngàn. -46164/3926...Quy đmh chu tiết và hướng dẫn thi hành một số điều của Nghị quyet so 198/2025/QH15 ngày 17 tháng 5 mnm 2025 cua Quốc hội về một số cơ chế, chmh sách đặc biệt phát triển kinh tế tư nhân | E27: Chính phủ | F27: 2026-01-15 | G27: đối chiếu trang 1 bản gốc | H27: 2026-01-15 | I27: tự động (regex) | J27: lực thi hành 1. Nghị định này có hiệu lực thi hành từ ngày ký | K27: active | N27: 198/2025/QH15 | R27: PDF scan (chụp hình) | S27: OCR | T27: Tesseract 5 (LSTM), ngôn ngữ vie | U27: 200 | V27: 89.1 | W27: 0.0405 | X27: 45
A28: ND141_2026 | B28: 141/2026/NĐ-CP | C28: Nghị định | D28: NGHỊ ĐỊNH Sửa đối, bồ sung một số điều của Nghị định số 68/2026/NĐ-CP quy định về chính sách thuế đối với hộ kinh doanh, cá nhân kinh doanh và Nghị định số 320/2025/NĐ-CP quy định chỉ tiết một số điều và biện pháp để tổ chức, R { R ` ˆ ”M ˆ .Ả ®ủGTHỎNGHNĐIÊNTỪCHÍNHPMÚ hướng dân thi hành `IJuz_lt Thuê thu nhập doanh nghiệp ế cứ Luật Tổ chức Chính phủ số 63/2025/QH15; | E28: Chính phủ | F28: 2026-04-29 | G28: đối chiếu trang 1 bản gốc | H28: 2026-01-01 | I28: tự động (regex) | J28: iệu lực thi Mmh Nghị định này có hiệu lực thi hành từ ngày 01 tháng 01 năm 2026 | K28: active | L28: 320/2025/NĐ-CP, 68/2026/NĐ-CP | R28: PDF scan (chụp hình) | S28: OCR | T28: Tesseract 5 (LSTM), ngôn ngữ vie | U28: 200 | V28: 89.1 | W28: 0.0387 | X28: 9
A29: ND245_2026 | B29: 245/2026/NĐ-CP | C29: Nghị định | D29: NGHỊ ĐỊNH Gia hạn thời hạn nộp thuế giá trị gia tăng, thuế thu nhập doanh nghiệp, thuế thu nhập cá nhân và tiền thuê đất trong năm 2026 | E29: Chính phủ | F29: 2026-06-27 | G29: đối chiếu trang 1 bản gốc | H29: 2026-06-27 | I29: tự động (regex) | J29: lực thi hành 1, Nghị định này có hiệu lực thi hành kể từ ngày ký | K29: active | R29: PDF scan (chụp hình) | S29: OCR | T29: Tesseract 5 (LSTM), ngôn ngữ vie | U29: 200 | V29: 88.3 | W29: 0.0519 | X29: 20
A30: TT20_2026_BTC | B30: 20/2026/TT-BTC | C30: Thông tư | D30: THÔNG TƯ Quy định chỉ tiết một số điều của Luật Thuế thu nhập doanh nghiệp và Nghị định số 320/2025/NĐ-CP ngày 15 tháng 12 năm 2025 của Chính phủ quy định chỉ tiết một số điều và biện pháp đề tổ chức, hướng dẫn thi hành Luật Thuế thu nhập doanh nghiệp | E30: Bộ Tài chính | F30: 2026-03-12 | G30: đối chiếu trang 1 bản gốc | H30: 2026-03-12 | I30: tự động (regex) | J30: lực thi hành l. Thông tư này có hiệu lực thi hành từ ngày 12 tháng 3 năm 2026 | K30: active | M30: 78/2014/TT-BTC | N30: 67/2025/QH15, 320/2025/NĐ-CP | R30: PDF scan (chụp hình) | S30: OCR | T30: Tesseract 5 (LSTM), ngôn ngữ vie | U30: 200 | V30: 89.4 | W30: 0.0354 | X30: 57
A31: ND68_2026 | B31: 68/2026/NĐ-CP | C31: Nghị định | D31: NGHỊ ĐỊNH Quy định về chính sách thuế và quản lý thuế đối với hộ kinh doanh, cá nhân kinh doanh | E31: Chính phủ | F31: 2026-03-05 | G31: đối chiếu trang 1 bản gốc | H31: 2026-03-05 | I31: tự động (regex) | J31: ệu lực thi hành Nghị định này có hiệu lực thi hành kể từ ngày ký | K31: active | O31: 141/2026/NĐ-CP | R31: PDF scan (chụp hình) | S31: OCR | T31: Tesseract 5 (LSTM), ngôn ngữ vie | U31: 200 | V31: 90.5 | W31: 0.0195 | X31: 41
A32: TT152_2025_BTC | B32: 152/2025/TT-BTC | C32: Thông tư | D32: THÔNG TƯ Hướng dẫn kế toán cho các hộ kinh doanh, cá nhân kinh doanh | E32: Bộ Tài chính | F32: 2025-12-31 | G32: đối chiếu trang 1 bản gốc | H32: 2026-01-01 | I32: tự động (regex) | J32: lực thi hành 1. Thông tư này có hiệu lực thi hành kể từ ngày 01/01/2026 | K32: active | R32: PDF scan (chụp hình) | S32: OCR | T32: Tesseract 5 (LSTM), ngôn ngữ vie | U32: 200 | V32: 88.4 | W32: 0.0485 | X32: 25
A33: TT18_2026_BTC | B33: 18/2026/TT-BTC | C33: Thông tư | D33: Thông tư quy định về hồ sơ, thủ tục quản lý thuế đối với hộ kinh doanh, cá nhân kinh doanh | E33: Bộ Tài chính | F33: 2026-03-05 | G33: đối chiếu trang 1 bản gốc | H33: 2026-03-05 | I33: tự động (regex) | J33: ực thi hành ! 1. Thông tư này có hiệu lực thi hành kể từ ngày ký | K33: active | M33: 40/2021/TT-BTC | O33: 50/2026/TT-BTC | R33: PDF scan (chụp hình) | S33: OCR | T33: Tesseract 5 (LSTM), ngôn ngữ vie | U33: 200 | V33: 84.7 | W33: 0.0884 | X33: 62
A34: TT50_2026_BTC | B34: 50/2026/TT-BTC | C34: Thông tư | D34: THÔNG TƯ Sửa đối, bố sung một số điều của Thông tư số 18/2026/TT-BTC ngày 05 tháng 3 năm 2026 của Bộ trưởng Bộ Tài chính quy định về hồ sơ, thủ tục quần lý thuế đối với hộ kinh đoanh, cá nhân kinh doanh | E34: Bộ Tài chính | F34: 2026-05-13 | G34: đối chiếu trang 1 bản gốc | H34: 2026-05-13 | I34: tự động (regex) | J34: lực thi hành 1. Thông tư này có hiệu lực thi hành kể từ ngày ký | K34: active | L34: 18/2026/TT-BTC | R34: PDF scan (chụp hình) | S34: OCR | T34: Tesseract 5 (LSTM), ngôn ngữ vie | U34: 200 | V34: 83.7 | W34: 0.1082 | X34: 30
A35: L59_2020_QH14 | B35: 59/2020/QH14 | C35: Luật | D35: LUẬT DOANH NGHIỆP | E35: Quốc hội | F35: 2020-06-17 | G35: tự động (regex) | H35: 2021-01-01 | I35: tự động (regex) | J35: ều khoản thị hành 1. Luật này có hiệu lực thi Hành từ ngày 01 tháng 01 năm 2021 | K35: active | O35: 03/2022/QH15, 76/2025/QH15 | Q35: 168/2025/NĐ-CP | R35: PDF scan (chụp hình) | S35: OCR | T35: Tesseract 5 (LSTM), ngôn ngữ vie | U35: 200 | V35: 89.6 | W35: 0.0321 | X35: 327
